Workbook

Sheet Genel
A1: Toplam | B1: Tarih | C1: 45658 | D1: 45659 | E1: 45660 | F1: 45661 | G1: 45662 | H1: 45663 | I1: 45664 | J1: 45665 | K1: 45666 | L1: 45667 | M1: 45668 | N1: 45669 | O1: 45670 | P1: 45671 | Q1: 45672 | R1: 45673 | S1: 45674 | T1: 45675 | U1: 45676 | V1: 45677 | W1: 45678 | X1: 45679 | Y1: 45680 | Z1: 45681 | AA1: 45682 | AB1: 45683 | AC1: 45684 | AD1: 45685 | AE1: 45686 | AF1: 45687 | AG1: 45688 | AH1: 45689 | AI1: 45690 | AJ1: 45691 | AK1: 45692 | AL1: 45693 | AM1: 45694 | AN1: 45695 | AO1: 45696 | AP1: 45697 | AQ1: 45698 | AR1: 45699 | AS1: 45700 | AT1: 45701 | AU1: 45702 | AV1: 45703 | AW1: 45704 | AX1: 45705 | AY1: 45706 | AZ1: 45707 | BA1: 45708 | BB1: 45709 | BC1: 45710 | BD1: 45711 | BE1: 45712 | BF1: 45713 | BG1: 45714 | BH1: 45715 | BI1: 45716 | BJ1: 45717 | BK1: 45718 | BL1: 45719 | BM1: 45720 | BN1: 45721 | BO1: 45722 | BP1: 45723 | BQ1: 45724 | BR1: 45725 | BS1: 45726 | BT1: 45727 | BU1: 45728 | BV1: 45729 | BW1: 45730 | BX1: 45731 | BY1: 45732 | BZ1: 45733 | CA1: 45734 | CB1: 45735 | CC1: 45736 | CD1: 45737 | CE1: 45738 | CF1: 45739 | CG1: 45740 | CH1: 45741 | CI1: 45742 | CJ1: 45743 | CK1: 45744 | CL1: 45745 | CM1: 45746 | CN1: 45747 | CO1: 45748 | CP1: 45749 | CQ1: 45750 | CR1: 45751 | CS1: 45752 | CT1: 45753 | CU1: 45754 | CV1: 45755 | CW1: 45756 | CX1: 45757 | CY1: 45758 | CZ1: 45759 | DA1: 45760 | DB1: 45761 | DC1: 45762 | DD1: 45763 | DE1: 45764 | DF1: 45765 | DG1: 45766 | DH1: 45767 | DI1: 45768 | DJ1: 45769 | DK1: 45770 | DL1: 45771 | DM1: 45772 | DN1: 45773 | DO1: 45774 | DP1: 45775 | DQ1: 45776 | DR1: 45777 | DS1: 45778 | DT1: 45779 | DU1: 45780 | DV1: 45781 | DW1: 45782 | DX1: 45783 | DY1: 45784 | DZ1: 45785 | EA1: 45786 | EB1: 45787 | EC1: 45788 | ED1: 45789 | EE1: 45790 | EF1: 45791 | EG1: 45792 | EH1: 45793 | EI1: 45794 | EJ1: 45795 | EK1: 45796 | EL1: 45797 | EM1: 45798 | EN1: 45799 | EO1: 45800 | EP1: 45801 | EQ1: 45802 | ER1: 45803 | ES1: 45804 | ET1: 45805 | EU1: 45806 | EV1: 45807 | EW1: 45808 | EX1: 45809 | EY1: 45810 | EZ1: 45811 | FA1: 45812 | FB1: 45813 | FC1: 45814 | FD1: 45815 | FE1: 45816 | FF1: 45817 | FG1: 45818 | FH1: 45819 | FI1: 45820 | FJ1: 45821 | FK1: 45822 | FL1: 45823 | FM1: 45824 | FN1: 45825 | FO1: 45826 | FP1: 45827 | FQ1: 45828 | FR1: 45829 | FS1: 45830 | FT1: 45831 | FU1: 45832 | FV1: 45833 | FW1: 45834 | FX1: 45835 | FY1: 45836 | FZ1: 45837 | GA1: 45838 | GB1: 45839 | GC1: 45840 | GD1: 45841 | GE1: 45842 | GF1: 45843 | GG1: 45844 | GH1: 45845 | GI1: 45846 | GJ1: 45847 | GK1: 45848 | GL1: 45849 | GM1: 45850 | GN1: 45851 | GO1: 45852 | GP1: 45853 | GQ1: 45854 | GR1: 45855 | GS1: 45856 | GT1: 45857 | GU1: 45858 | GV1: 45859 | GW1: 45860 | GX1: 45861 | GY1: 45862 | GZ1: 45863 | HA1: 45864 | HB1: 45865 | HC1: 45866 | HD1: 45867 | HE1: 45868 | HF1: 45869 | HG1: 45870 | HH1: 45871 | HI1: 45872 | HJ1: 45873 | HK1: 45874 | HL1: 45875 | HM1: 45876 | HN1: 45877 | HO1: 45878 | HP1: 45879 | HQ1: 45880 | HR1: 45881 | HS1: 45882 | HT1: 45883 | HU1: 45884 | HV1: 45885 | HW1: 45886 | HX1: 45887 | HY1: 45888 | HZ1: 45889 | IA1: 45890 | IB1: 45891 | IC1: 45892 | ID1: 45893 | IE1: 45894 | IF1: 45895 | IG1: 45896 | IH1: 45897 | II1: 45898 | IJ1: 45899 | IK1: 45900 | IL1: 45901 | IM1: 45902 | IN1: 45903 | IO1: 45904 | IP1: 45905 | IQ1: 45906 | IR1: 45907 | IS1: 45908 | IT1: 45909 | IU1: 45910 | IV1: 45911 | IW1: 45912 | IX1: 45913 | IY1: 45914 | IZ1: 45915 | JA1: 45916 | JB1: 45917 | JC1: 45918 | JD1: 45919 | JE1: 45920 | JF1: 45921 | JG1: 45922 | JH1: 45923 | JI1: 45924 | JJ1: 45925 | JK1: 45926 | JL1: 45927 | JM1: 45928 | JN1: 45929 | JO1: 45930 | JP1: 45931 | JQ1: 45932 | JR1: 45933 | JS1: 45934 | JT1: 45935 | JU1: 45936 | JV1: 45937 | JW1: 45938 | JX1: 45939 | JY1: 45940 | JZ1: 45941 | KA1: 45942 | KB1: 45943 | KC1: 45944 | KD1: 45945 | KE1: 45946 | KF1: 45947 | KG1: 45948 | KH1: 45949 | KI1: 45950 | KJ1: 45951 | KK1: 45952 | KL1: 45953 | KM1: 45954 | KN1: 45955 | KO1: 45956 | KP1: 45957 | KQ1: 45958 | KR1: 45959 | KS1: 45960 | KT1: 45961 | KU1: 45962 | KV1: 45963 | KW1: 45964 | KX1: 45965 | KY1: 45966 | KZ1: 45967 | LA1: 45968 | LB1: 45969 | LC1: 45970 | LD1: 45971 | LE1: 45972 | LF1: 45973 | LG1: 45974 | LH1: 45975 | LI1: 45976 | LJ1: 45977 | LK1: 45978 | LL1: 45979 | LM1: 45980 | LN1: 45981 | LO1: 45982 | LP1: 45983 | LQ1: 45984 | LR1: 45985 | LS1: 45986 | LT1: 45987 | LU1: 45988 | LV1: 45989 | LW1: 45990 | LX1: 45991 | LY1: 45992 | LZ1: 45993 | MA1: 45994 | MB1: 45995 | MC1: 45996 | MD1: 45997 | ME1: 45998 | MF1: 45999 | MG1: 46000 | MH1: 46001 | MI1: 46002 | MJ1: 46003 | MK1: 46004 | ML1: 46005 | MM1: 46006 | MN1: 46007 | MO1: 46008 | MP1: 46009 | MQ1: 46010 | MR1: 46011 | MS1: 46012 | MT1: 46013 | MU1: 46014 | MV1: 46015 | MW1: 46016 | MX1: 46017 | MY1: 46018 | MZ1: 46019 | NA1: 46020 | NB1: 46021 | NC1: 46022
B2: Hafta | C2: 1. Hafta | D2: 1. Hafta | E2: 1. Hafta | F2: 1. Hafta | G2: 1. Hafta | H2: 2. Hafta | I2: 2. Hafta | J2: 2. Hafta | K2: 2. Hafta | L2: 2. Hafta | M2: 2. Hafta | N2: 2. Hafta | O2: 3. Hafta | P2: 3. Hafta | Q2: 3. Hafta | R2: 3. Hafta | S2: 3. Hafta | T2: 3. Hafta | U2: 3. Hafta | V2: 4. Hafta | W2: 4. Hafta | X2: 4. Hafta | Y2: 4. Hafta | Z2: 4. Hafta | AA2: 4. Hafta | AB2: 4. Hafta | AC2: 5. Hafta | AD2: 5. Hafta | AE2: 5. Hafta | AF2: 5. Hafta | AG2: 5. Hafta | AH2: 5. Hafta | AI2: 5. Hafta | AJ2: 6. Hafta | AK2: 6. Hafta | AL2: 6. Hafta | AM2: 6. Hafta | AN2: 6. Hafta | AO2: 6. Hafta | AP2: 6. Hafta | AQ2: 7. Hafta | AR2: 7. Hafta | AS2: 7. Hafta | AT2: 7. Hafta | AU2: 7. Hafta | AV2: 7. Hafta | AW2: 7. Hafta | AX2: 8. Hafta | AY2: 8. Hafta | AZ2: 8. Hafta | BA2: 8. Hafta | BB2: 8. Hafta | BC2: 8. Hafta | BD2: 8. Hafta | BE2: 9. Hafta | BF2: 9. Hafta | BG2: 9. Hafta | BH2: 9. Hafta | BI2: 9. Hafta | BJ2: 9. Hafta | BK2: 9. Hafta | BL2: 10. Hafta | BM2: 10. Hafta | BN2: 10. Hafta | BO2: 10. Hafta | BP2: 10. Hafta | BQ2: 10. Hafta | BR2: 10. Hafta | BS2: 11. Hafta | BT2: 11. Hafta | BU2: 11. Hafta | BV2: 11. Hafta | BW2: 11. Hafta | BX2: 11. Hafta | BY2: 11. Hafta | BZ2: 12. Hafta | CA2: 12. Hafta | CB2: 12. Hafta | CC2: 12. Hafta | CD2: 12. Hafta | CE2: 12. Hafta | CF2: 12. Hafta | CG2: 13. Hafta | CH2: 13. Hafta | CI2: 13. Hafta | CJ2: 13. Hafta | CK2: 13. Hafta | CL2: 13. Hafta | CM2: 13. Hafta | CN2: 14. Hafta | CO2: 14. Hafta | CP2: 14. Hafta | CQ2: 14. Hafta | CR2: 14. Hafta | CS2: 14. Hafta | CT2: 14. Hafta | CU2: 15. Hafta | CV2: 15. Hafta | CW2: 15. Hafta | CX2: 15. Hafta | CY2: 15. Hafta | CZ2: 15. Hafta | DA2: 15. Hafta | DB2: 16. Hafta | DC2: 16. Hafta | DD2: 16. Hafta | DE2: 16. Hafta | DF2: 16. Hafta | DG2: 16. Hafta | DH2: 16. Hafta | DI2: 17. Hafta | DJ2: 17. Hafta | DK2: 17. Hafta | DL2: 17. Hafta | DM2: 17. Hafta | DN2: 17. Hafta | DO2: 17. Hafta | DP2: 18. Hafta | DQ2: 18. Hafta | DR2: 18. Hafta | DS2: 18. Hafta | DT2: 18. Hafta | DU2: 18. Hafta | DV2: 18. Hafta | DW2: 19. Hafta | DX2: 19. Hafta | DY2: 19. Hafta | DZ2: 19. Hafta | EA2: 19. Hafta | EB2: 19. Hafta | EC2: 19. Hafta | ED2: 20. Hafta | EE2: 20. Hafta | EF2: 20. Hafta | EG2: 20. Hafta | EH2: 20. Hafta | EI2: 20. Hafta | EJ2: 20. Hafta | EK2: 21. Hafta | EL2: 21. Hafta | EM2: 21. Hafta | EN2: 21. Hafta | EO2: 21. Hafta | EP2: 21. Hafta | EQ2: 21. Hafta | ER2: 22. Hafta | ES2: 22. Hafta | ET2: 22. Hafta | EU2: 22. Hafta | EV2: 22. Hafta | EW2: 22. Hafta | EX2: 22. Hafta | EY2: 23. Hafta | EZ2: 23. Hafta | FA2: 23. Hafta | FB2: 23. Hafta | FC2: 23. Hafta | FD2: 23. Hafta | FE2: 23. Hafta | FF2: 24. Hafta | FG2: 24. Hafta | FH2: 24. Hafta | FI2: 24. Hafta | FJ2: 24. Hafta | FK2: 24. Hafta | FL2: 24. Hafta | FM2: 25. Hafta | FN2: 25. Hafta | FO2: 25. Hafta | FP2: 25. Hafta | FQ2: 25. Hafta | FR2: 25. Hafta | FS2: 25. Hafta | FT2: 26. Hafta | FU2: 26. Hafta | FV2: 26. Hafta | FW2: 26. Hafta | FX2: 26. Hafta | FY2: 26. Hafta | FZ2: 26. Hafta | GA2: 27. Hafta | GB2: 27. Hafta | GC2: 27. Hafta | GD2: 27. Hafta | GE2: 27. Hafta | GF2: 27. Hafta | GG2: 27. Hafta | GH2: 28. Hafta | GI2: 28. Hafta | GJ2: 28. Hafta | GK2: 28. Hafta | GL2: 28. Hafta | GM2: 28. Hafta | GN2: 28. Hafta | GO2: 29. Hafta | GP2: 29. Hafta | GQ2: 29. Hafta | GR2: 29. Hafta | GS2: 29. Hafta | GT2: 29. Hafta | GU2: 29. Hafta | GV2: 30. Hafta | GW2: 30. Hafta | GX2: 30. Hafta | GY2: 30. Hafta | GZ2: 30. Hafta | HA2: 30. Hafta | HB2: 30. Hafta | HC2: 31. Hafta | HD2: 31. Hafta | HE2: 31. Hafta | HF2: 31. Hafta | HG2: 31. Hafta | HH2: 31. Hafta | HI2: 31. Hafta | HJ2: 32. Hafta | HK2: 32. Hafta | HL2: 32. Hafta | HM2: 32. Hafta | HN2: 32. Hafta | HO2: 32. Hafta | HP2: 32. Hafta | HQ2: 33. Hafta | HR2: 33. Hafta | HS2: 33. Hafta | HT2: 33. Hafta | HU2: 33. Hafta | HV2: 33. Hafta | HW2: 33. Hafta | HX2: 34. Hafta | HY2: 34. Hafta | HZ2: 34. Hafta | IA2: 34. Hafta | IB2: 34. Hafta | IC2: 34. Hafta | ID2: 34. Hafta | IE2: 35. Hafta | IF2: 35. Hafta | IG2: 35. Hafta | IH2: 35. Hafta | II2: 35. Hafta | IJ2: 35. Hafta | IK2: 35. Hafta | IL2: 36. Hafta | IM2: 36. Hafta | IN2: 36. Hafta | IO2: 36. Hafta | IP2: 36. Hafta | IQ2: 36. Hafta | IR2: 36. Hafta | IS2: 37. Hafta | IT2: 37. Hafta | IU2: 37. Hafta | IV2: 37. Hafta | IW2: 37. Hafta | IX2: 37. Hafta | IY2: 37. Hafta | IZ2: 38. Hafta | JA2: 38. Hafta | JB2: 38. Hafta | JC2: 38. Hafta | JD2: 38. Hafta | JE2: 38. Hafta | JF2: 38. Hafta | JG2: 39. Hafta | JH2: 39. Hafta | JI2: 39. Hafta | JJ2: 39. Hafta | JK2: 39. Hafta | JL2: 39. Hafta | JM2: 39. Hafta | JN2: 40. Hafta | JO2: 40. Hafta | JP2: 40. Hafta | JQ2: 40. Hafta | JR2: 40. Hafta | JS2: 40. Hafta | JT2: 40. Hafta | JU2: 41. Hafta | JV2: 41. Hafta | JW2: 41. Hafta | JX2: 41. Hafta | JY2: 41. Hafta | JZ2: 41. Hafta | KA2: 41. Hafta | KB2: 42. Hafta | KC2: 42. Hafta | KD2: 42. Hafta | KE2: 42. Hafta | KF2: 42. Hafta | KG2: 42. Hafta | KH2: 42. Hafta | KI2: 43. Hafta | KJ2: 43. Hafta | KK2: 43. Hafta | KL2: 43. Hafta | KM2: 43. Hafta | KN2: 43. Hafta | KO2: 43. Hafta | KP2: 44. Hafta | KQ2: 44. Hafta | KR2: 44. Hafta | KS2: 44. Hafta | KT2: 44. Hafta | KU2: 44. Hafta | KV2: 44. Hafta | KW2: 45. Hafta | KX2: 45. Hafta | KY2: 45. Hafta | KZ2: 45. Hafta | LA2: 45. Hafta | LB2: 45. Hafta | LC2: 45. Hafta | LD2: 46. Hafta | LE2: 46. Hafta | LF2: 46. Hafta | LG2: 46. Hafta | LH2: 46. Hafta | LI2: 46. Hafta | LJ2: 46. Hafta | LK2: 47. Hafta | LL2: 47. Hafta | LM2: 47. Hafta | LN2: 47. Hafta | LO2: 47. Hafta | LP2: 47. Hafta | LQ2: 47. Hafta | LR2: 48. Hafta | LS2: 48. Hafta | LT2: 48. Hafta | LU2: 48. Hafta | LV2: 48. Hafta | LW2: 48. Hafta | LX2: 48. Hafta | LY2: 49. Hafta | LZ2: 49. Hafta | MA2: 49. Hafta | MB2: 49. Hafta | MC2: 49. Hafta | MD2: 49. Hafta | ME2: 49. Hafta | MF2: 50. Hafta | MG2: 50. Hafta | MH2: 50. Hafta | MI2: 50. Hafta | MJ2: 50. Hafta | MK2: 50. Hafta | ML2: 50. Hafta | MM2: 51. Hafta | MN2: 51. Hafta | MO2: 51. Hafta | MP2: 51. Hafta | MQ2: 51. Hafta | MR2: 51. Hafta | MS2: 51. Hafta | MT2: 52. Hafta | MU2: 52. Hafta | MV2: 52. Hafta | MW2: 52. Hafta | MX2: 52. Hafta | MY2: 52. Hafta | MZ2: 52. Hafta | NA2: 1. Hafta | NB2: 1. Hafta | NC2: 1. Hafta
A3: =SUM(C3:NC3) -> 1270430.2 | B3: Gerçekleşen Çalışma Saat | D3: 3669.9167 | E3: 3620.0833 | F3: 2201.5833 | G3: 1794.4167 | H3: 3518.6667 | I3: 3217.1667 | J3: 3283.3333 | K3: 3279.0833 | L3: 3231.5833 | M3: 1865.0833 | N3: 1768.4167 | O3: 3075.8333 | P3: 3198.5 | Q3: 3620.3333 | R3: 3810.9167 | S3: 3510.0833 | T3: 2065.25 | U3: 1724 | V3: 3434 | W3: 3562.6667 | X3: 3435.1667 | Y3: 2864.25 | Z3: 3009.25 | AA3: 2037.4167 | AB3: 1803.4167 | AC3: 2864.1667 | AD3: 2774.9167 | AE3: 2926.5833 | AF3: 2960.25 | AG3: 2597.8333 | AH3: 1822.4167 | AI3: 1723.1667 | AJ3: 2523.9167 | AK3: 2724 | AL3: 3169.4167 | AM3: 3054.1667 | AN3: 3181.3333 | AO3: 1844.4167 | AP3: 1584.25 | AQ3: 2897.4167 | AR3: 3475.6667 | AS3: 3254.1667 | AT3: 3074.8333 | AU3: 2520.6667 | AV3: 1339.5833 | AW3: 1546.5833 | AX3: 3002.1667 | AY3: 3199.0833 | AZ3: 3094.0833 | BA3: 2965.0833 | BB3: 2536.75 | BC3: 859.75 | BD3: 1098.5833 | BE3: 3240.8333 | BF3: 3005.9167 | BG3: 3129.25 | BH3: 2782 | BI3: 2570.5 | BJ3: 1391.0833 | BK3: 732 | BL3: 2847.6667 | BM3: 2798.9167 | BN3: 2778.0833 | BO3: 2822 | BP3: 3137.9167 | BQ3: 2661.5033 | BR3: 1503.3333 | BS3: 4413.1667 | BT3: 3918.5 | BU3: 3807.6667 | BV3: 3990.5833 | BW3: 3888.5833 | BX3: 2560 | BY3: 1412.0833 | BZ3: 4755.0833 | CA3: 5274.3333 | CB3: 5029.25 | CC3: 5199.3333 | CD3: 5182.5 | CE3: 4447.8333 | CF3: 4378 | CG3: 5223.6667 | CH3: 5286.0833 | CI3: 4191.4167 | CJ3: 3247.5833 | CK3: 3195.9167 | CL3: 869.75 | CP3: 2833.0833 | CQ3: 3679.4167 | CR3: 3130.25 | CS3: 2021.8333 | CT3: 1779.9167 | CU3: 2980.3333 | CV3: 2928.9167 | CW3: 2959.3333 | CX3: 3026.4167 | CY3: 3527.5 | CZ3: 2005.75 | DA3: 1482.75 | DB3: 3593.0833 | DC3: 3937.3333 | DD3: 3643.0833 | DE3: 3648.25 | DF3: 3584.6667 | DG3: 1907.5 | DH3: 1915.8333 | DI3: 3663.5 | DJ3: 3372.3333 | DK3: 655.6 | DM3: 4370.1667 | DN3: 4107 | DO3: 2919.1667 | DP3: 3076.25 | DQ3: 3169.4167 | DR3: 3581.0833 | DT3: 4170.3333 | DU3: 2668.5 | DV3: 1284.25 | DW3: 4269 | DX3: 4087.5 | DY3: 4287.75 | DZ3: 4165.4167 | EA3: 4188.25 | EB3: 2556 | EC3: 1339.8333 | ED3: 5161.9167 | EE3: 4563.1667 | EF3: 4493.8333 | EG3: 4282 | EH3: 4279.5 | EI3: 2679.5833 | EJ3: 1418.75 | EK3: 5278.6667 | EL3: 4829.0833 | EM3: 5236.75 | EN3: 4849 | EO3: 4411.75 | EP3: 3887.8333 | EQ3: 1557.5833 | ER3: 5328.1667 | ES3: 5470.8333 | ET3: 5428.8333 | EU3: 5474.8333 | EV3: 5395.0833 | EW3: 5636.6667 | EX3: 4580.1667 | EY3: 4415.9167 | EZ3: 3913.5 | FA3: 3266.6667 | FB3: 1706.0833 | FG3: 4655.5 | FH3: 4979.8333 | FI3: 5029.6667 | FJ3: 5177.5 | FK3: 5372.25 | FL3: 4733.75 | FM3: 4652.9167 | FN3: 4748.5833 | FO3: 5172.3333 | FP3: 5093.4167 | FQ3: 4387.8333 | FR3: 3351.1667 | FS3: 1318.25 | FT3: 4802 | FU3: 4359.75 | FV3: 4567.8333 | FW3: 4381.9167 | FX3: 4780.9167 | FY3: 3636.4167 | FZ3: 1367 | GA3: 4963.75 | GB3: 4697 | GC3: 3897.75 | GD3: 4251.8333 | GE3: 3489.9167 | GF3: 2660.5 | GG3: 1201.9167 | GH3: 3648.0833 | GI3: 4254.75 | GJ3: 4472.25 | GK3: 4013.5833 | GL3: 3698.3333 | GM3: 2746 | GN3: 1256.3333 | GO3: 3721.6667 | GQ3: 4767.0833 | GR3: 4556 | GS3: 4551.9167 | GT3: 4144.5 | GU3: 2730.6667 | GV3: 3066.5 | GW3: 2940.3333 | GX3: 3117 | GY3: 3046.1667 | GZ3: 3098.5 | HA3: 1730.5 | HB3: 1391.3333 | HC3: 3228.25 | HD3: 3247.6667 | HE3: 3242.3333 | HF3: 3184.4167 | HG3: 3127.5 | HH3: 1757.8333 | HI3: 1328.25 | HJ3: 3176.0833 | HK3: 2885.5833 | HL3: 2913.25 | HM3: 2887.1667 | HN3: 2859.6667 | HO3: 1607.5833 | HP3: 1219.8333 | HQ3: 3020.5833 | HR3: 3041.75 | HS3: 2961.4167 | HT3: 2970.4167 | HU3: 2662.3333 | HV3: 1569.4167 | HW3: 1219.5 | HX3: 2870.8333 | HY3: 2926.0833 | HZ3: 2680.6667 | IA3: 3094.9167 | IB3: 2821.4167 | IC3: 2777.9167 | ID3: 2702.9167 | IE3: 3163.5 | IF3: 3104.5833 | IG3: 3674.25 | IH3: 3660.6667 | II3: 3556.1667 | IJ3: 2953.0833 | IK3: 2785.5 | IL3: 3153.3333 | IM3: 3228.0833 | IN3: 3229.25 | IO3: 3113.4167 | IP3: 3085.9167 | IQ3: 2788.75 | IR3: 2723 | IS3: 3588.9167 | IT3: 4019 | IU3: 4636 | IV3: 5028.3333 | IW3: 4383.1667 | IX3: 2933.5833 | IY3: 1883.3333 | IZ3: 3980.6667 | JA3: 4040 | JB3: 3851.4167 | JC3: 3562.8333 | JD3: 3515.6667 | JE3: 1894.5 | JF3: 1812.0833 | JG3: 3681.5833 | JH3: 4170.5 | JI3: 4376.0833 | JJ3: 4421.5 | JK3: 3969.0833 | JL3: 1929.8333 | JM3: 1846.5833 | JN3: 4461.3333 | JO3: 4649.4167 | JP3: 4449.5833 | JQ3: 4199.6667 | JR3: 3876.0833 | JS3: 1967.5 | JT3: 1850.9167 | JU3: 3892.5833 | JV3: 3933.6833 | JW3: 4912.4167 | JX3: 5089.3333 | JY3: 4887.5 | JZ3: 3191.5833 | KA3: 1811.4167 | KB3: 5508.25 | KC3: 5620.1667 | KD3: 6043.75 | KE3: 6085.9167 | KF3: 5746 | KG3: 5513.75 | KH3: 3894 | KI3: 5589.25 | KJ3: 5799.25 | KK3: 6031.1667 | KL3: 5954.5 | KM3: 5734.8333 | KN3: 3728.1667 | KO3: 2947.5 | KP3: 6445.6667 | KQ3: 6124.3333 | KR3: 6044.25 | KS3: 5837.4167 | KT3: 6378.75 | KU3: 3486.6667 | KV3: 2225.5 | KW3: 6425.4167 | KX3: 6592.8333 | KY3: 5842.1667 | KZ3: 4790.25 | LA3: 4658.25 | LB3: 2626 | LC3: 2390.1667 | LD3: 4880.6667 | LE3: 4930 | LF3: 4868.5 | LG3: 5041.25 | LH3: 4971.5833 | LI3: 2696.4167 | LJ3: 2383.75 | LK3: 5505.5833 | LL3: 5401.3333 | LM3: 4922.3333 | LN3: 4853.9167 | LO3: 4865.5 | LP3: 2653.0833 | LQ3: 2377.5833 | LR3: 4677.25 | LS3: 4656.9167 | LT3: 4679.1667 | LU3: 5295.5 | LV3: 5260.5 | LW3: 3251.6667 | LX3: 2178.75 | LY3: 5887.3159 | LZ3: 5808.7309 | MA3: 5423.7943 | MB3: 5682.3435 | MC3: 5216.9252 | MD3: 3190.3407 | ME3: 2172.3464 | MF3: 5276.3753 | MG3: 5706.9825 | MH3: 5757.4743 | MI3: 5269.0218 | MJ3: 4838.8238 | MK3: 2867.3889 | ML3: 2114.6667 | MM3: 4165.2853 | MN3: 4292.785 | MO3: 4377.3293 | MP3: 4455.9587 | MQ3: 4184.9291 | MR3: 4078.5569 | MS3: 4097.3251 | MT3: 4216.0833 | MU3: 3954.25 | MV3: 3949.4167 | MW3: 3969.75 | MX3: 3950.0833 | MY3: 2278.25 | MZ3: 2164.75 | NA3: 3826.25 | NB3: 3730.1667 | NC3: 2574.5833
A4: =SUM(C4:NC4) -> 46561483 | B4: Gerçekleşen Adet | D4: 112272 | E4: 100571 | F4: 64283 | G4: 53705 | H4: 78875 | I4: 85934 | J4: 98481 | K4: 109676 | L4: 97587 | M4: 62782 | N4: 65347 | O4: 83397 | P4: 76464 | Q4: 95772 | R4: 163666 | S4: 136593 | T4: 71777 | U4: 73898 | V4: 84392 | W4: 115558 | X4: 94829 | Y4: 91123 | Z4: 84949 | AA4: 66709 | AB4: 68922 | AC4: 63112 | AD4: 76940 | AE4: 89449 | AF4: 111380 | AG4: 80937 | AH4: 68663 | AI4: 68499 | AJ4: 65276 | AK4: 95962 | AL4: 102488 | AM4: 122309 | AN4: 136825 | AO4: 91682 | AP4: 77478 | AQ4: 121851 | AR4: 146953 | AS4: 128380 | AT4: 118994 | AU4: 86037 | AV4: 47577 | AW4: 62152 | AX4: 87656 | AY4: 124963 | AZ4: 134000 | BA4: 121443 | BB4: 83957 | BC4: 35647 | BD4: 46036 | BE4: 137132 | BF4: 121965 | BG4: 125239 | BH4: 113913 | BI4: 86359 | BJ4: 65051 | BK4: 24869 | BL4: 118917 | BM4: 112453 | BN4: 126662 | BO4: 149701 | BP4: 127933 | BQ4: 116549 | BR4: 65109 | BS4: 183552 | BT4: 170370 | BU4: 165829 | BV4: 157981 | BW4: 153950 | BX4: 118516 | BY4: 66734 | BZ4: 195308 | CA4: 207982 | CB4: 148771 | CC4: 234873 | CD4: 206330 | CE4: 185973 | CF4: 200735 | CG4: 229540 | CH4: 223857 | CI4: 188537 | CJ4: 125341 | CK4: 95520 | CL4: 34156 | CP4: 151135 | CQ4: 181697 | CR4: 124201 | CS4: 99036 | CT4: 70587 | CU4: 101993 | CV4: 119643 | CW4: 120660 | CX4: 115500 | CY4: 117091 | CZ4: 100997 | DA4: 66893 | DB4: 146527 | DC4: 146149 | DD4: 159848 | DE4: 173715 | DF4: 155339 | DG4: 82863 | DH4: 83020 | DI4: 117436 | DJ4: 129319 | DK4: 33313 | DM4: 124585 | DN4: 159769 | DO4: 137155 | DP4: 118043 | DQ4: 118024 | DR4: 113793 | DT4: 160525 | DU4: 123501 | DV4: 74789 | DW4: 168460 | DX4: 165984 | DY4: 179698 | DZ4: 168583 | EA4: 171544 | EB4: 117670 | EC4: 69342 | ED4: 200496 | EE4: 153713 | EF4: 167963 | EG4: 184208 | EH4: 154502 | EI4: 115669 | EJ4: 68451 | EK4: 161698 | EL4: 194175 | EM4: 184357 | EN4: 202925 | EO4: 176237 | EP4: 122700 | EQ4: 67145 | ER4: 183290 | ES4: 211448 | ET4: 213572 | EU4: 213646 | EV4: 206946 | EW4: 237238 | EX4: 187680 | EY4: 206743 | EZ4: 162268 | FA4: 85896 | FB4: 43934 | FG4: 115252 | FH4: 190850 | FI4: 190826 | FJ4: 186095 | FK4: 205995 | FL4: 192365 | FM4: 189360 | FN4: 187350 | FO4: 176527 | FP4: 214254 | FQ4: 158649 | FR4: 141784 | FS4: 56689 | FT4: 137509 | FU4: 131670 | FV4: 170743 | FW4: 156646 | FX4: 184067 | FY4: 134937 | FZ4: 67947 | GA4: 176223 | GB4: 191012 | GC4: 136109 | GD4: 163120 | GE4: 127130 | GF4: 77220 | GG4: 49123 | GH4: 91732 | GI4: 140810 | GJ4: 167834 | GK4: 147667 | GL4: 129191 | GM4: 111857 | GN4: 55959 | GO4: 95558 | GQ4: 168204 | GR4: 144463 | GS4: 176674 | GT4: 187456 | GU4: 160892 | GV4: 114555 | GW4: 106171 | GX4: 130055 | GY4: 111382 | GZ4: 115143 | HA4: 72124 | HB4: 61822 | HC4: 122307 | HD4: 96343 | HE4: 130204 | HF4: 114530 | HG4: 138060 | HH4: 65557 | HI4: 65632 | HJ4: 128110 | HK4: 112558 | HL4: 107462 | HM4: 95038 | HN4: 107357 | HO4: 61082 | HP4: 64124 | HQ4: 126492 | HR4: 113416 | HS4: 129851 | HT4: 109390 | HU4: 101029 | HV4: 59960 | HW4: 55064 | HX4: 105397 | HY4: 82477 | HZ4: 98667 | IA4: 135820 | IB4: 117300 | IC4: 123319 | ID4: 107847 | IE4: 126452 | IF4: 108806 | IG4: 147516 | IH4: 140935 | II4: 140064 | IJ4: 124289 | IK4: 108403 | IL4: 132554 | IM4: 134458 | IN4: 126790 | IO4: 121637 | IP4: 101770 | IQ4: 145749 | IR4: 99087 | IS4: 120281 | IT4: 143028 | IU4: 165327 | IV4: 171410 | IW4: 177632 | IX4: 116155 | IY4: 57650 | IZ4: 146853 | JA4: 143001 | JB4: 181505 | JC4: 151021 | JD4: 112709 | JE4: 83419 | JF4: 74482 | JG4: 133599 | JH4: 173594 | JI4: 162614 | JJ4: 183167 | JK4: 180234 | JL4: 84488 | JM4: 67238 | JN4: 145944 | JO4: 189656 | JP4: 162989 | JQ4: 168481 | JR4: 137762 | JS4: 84001 | JT4: 72512 | JU4: 149075 | JV4: 164266 | JW4: 173891 | JX4: 187607 | JY4: 179760 | JZ4: 103215 | KA4: 76354 | KB4: 181138 | KC4: 171842 | KD4: 203447 | KE4: 213845 | KF4: 214373 | KG4: 216578 | KH4: 153818 | KI4: 199107 | KJ4: 215894 | KK4: 203954 | KL4: 212985 | KM4: 197455 | KN4: 145735 | KO4: 112433 | KP4: 196571 | KQ4: 202583 | KR4: 211064 | KS4: 174986 | KT4: 156181 | KU4: 99474 | KV4: 84537 | KW4: 158534 | KX4: 194645 | KY4: 188010 | KZ4: 167672 | LA4: 86129 | LB4: 99585 | LC4: 89670 | LD4: 115079 | LE4: 117252 | LF4: 130169 | LG4: 159640 | LH4: 141938 | LI4: 97736 | LJ4: 97473 | LK4: 161106 | LL4: 176181 | LM4: 169266 | LN4: 139131 | LO4: 159346 | LP4: 81720 | LQ4: 75000 | LR4: 111431 | LS4: 145629 | LT4: 159338 | LU4: 187738 | LV4: 143780 | LW4: 87582 | LX4: 82023 | LY4: 173818 | LZ4: 167365 | MA4: 175196 | MB4: 196679 | MC4: 188590 | MD4: 103167 | ME4: 79031 | MF4: 162076 | MG4: 188867 | MH4: 196941 | MI4: 200233 | MJ4: 196835 | MK4: 111542 | ML4: 84103 | MM4: 127258 | MN4: 130803 | MO4: 137569 | MP4: 135661 | MQ4: 162736 | MR4: 156219 | MS4: 150429 | MT4: 148489 | MU4: 129343 | MV4: 139498 | MW4: 142075 | MX4: 135716 | MY4: 99661 | MZ4: 101167 | NA4: 136048 | NB4: 148075 | NC4: 113424
A5: =+A4/A3 -> 36.650169 | B5: Gerçekleşen Verimlilik | D5: =+D4/D3 -> 30.59252 | E5: =+E4/E3 -> 27.781405 | F5: =+F4/F3 -> 29.198531 | G5: =+G4/G3 -> 29.928946 | H5: =+H4/H3 -> 22.416161 | I5: =+I4/I3 -> 26.711081 | J5: =+J4/J3 -> 29.994213 | K5: =+K4/K3 -> 33.447152 | ... CL5: =+CL4/CL3 -> 39.271055 | CP5: =+CP4/CP3 -> 53.346472 | CQ5: =+CQ4/CQ3 -> 49.382013 | CR5: =+CR4/CR3 -> 39.677662 | CS5: =+CS4/CS3 -> 48.983266 | CT5: =+CT4/CT3 -> 39.657475 | CU5: =+CU4/CU3 -> 34.222011 | CV5: =+CV4/CV3 -> 40.848892 | CW5: =+CW4/CW3 -> 40.772697 | ... DK5: =+DK4/DK3 -> 50.812996 | DM5: =+DM4/DM3 -> 28.508066 | DN5: =+DN4/DN3 -> 38.901631 | DO5: =+DO4/DO3 -> 46.984299 | DP5: =+DP4/DP3 -> 38.372369 | DQ5: =+DQ4/DQ3 -> 37.238398 | DR5: =+DR4/DR3 -> 31.776139 | DT5: =+DT4/DT3 -> 38.492127 | DU5: =+DU4/DU3 -> 46.281057 | DV5: =+DV4/DV3 -> 58.235546 | DW5: =+DW4/DW3 -> 39.461232 | DX5: =+DX4/DX3 -> 40.607706 | DY5: =+DY4/DY3 -> 41.909626 | DZ5: =+DZ4/DZ3 -> 40.472062 | EA5: =+EA4/EA3 -> 40.958396 | ... FB5: =+FB4/FB3 -> 25.75138 | FG5: =+FG4/FG3 -> 24.756095 | FH5: =+FH4/FH3 -> 38.324576 | FI5: =+FI4/FI3 -> 37.940089 | FJ5: =+FJ4/FJ3 -> 35.943023 | FK5: =+FK4/FK3 -> 38.344269 | FL5: =+FL4/FL3 -> 40.636916 | FM5: =+FM4/FM3 -> 40.697054 | FN5: =+FN4/FN3 -> 39.453872 | ... GO5: =+GO4/GO3 -> 25.676131 | GQ5: =+GQ4/GQ3 -> 35.284468 | GR5: =+GR4/GR3 -> 31.708297 | GS5: =+GS4/GS3 -> 38.813101 | GT5: =+GT4/GT3 -> 45.230064 | GU5: =+GU4/GU3 -> 58.92041 | GV5: =+GV4/GV3 -> 37.356922 | GW5: =+GW4/GW3 -> 36.108491 | GX5: =+GX4/GX3 -> 41.724415 | ... NC5: =+NC4/NC3 -> 44.055284
A7: Toplam | B7: Tarih | C7: 46023 | D7: =+C7+1 -> 46024 | E7: =+D7+1 -> 46025 | F7: =+E7+1 -> 46026 | G7: =+F7+1 -> 46027 | H7: =+G7+1 -> 46028 | I7: =+H7+1 -> 46029 | J7: =+I7+1 -> 46030 | K7: =+J7+1 -> 46031 | ... NC7: =+NB7+1 -> 46387
B8: Hafta | C8: 1. Hafta | D8: 1. Hafta | E8: 1. Hafta | F8: 1. Hafta | G8: 2. Hafta | H8: 2. Hafta | I8: 2. Hafta | J8: 2. Hafta | K8: 2. Hafta | L8: 2. Hafta | M8: 2. Hafta | N8: 3. Hafta | O8: 3. Hafta | P8: 3. Hafta | Q8: 3. Hafta | R8: 3. Hafta | S8: 3. Hafta | T8: 3. Hafta | U8: 4. Hafta | V8: 4. Hafta | W8: 4. Hafta | X8: 4. Hafta | Y8: 4. Hafta | Z8: 4. Hafta | AA8: 4. Hafta | AB8: 5. Hafta | AC8: 5. Hafta | AD8: 5. Hafta | AE8: 5. Hafta | AF8: 5. Hafta | AG8: 5. Hafta | AH8: 5. Hafta | AI8: 6. Hafta | AJ8: 6. Hafta | AK8: 6. Hafta | AL8: 6. Hafta | AM8: 6. Hafta | AN8: 6. Hafta | AO8: 6. Hafta | AP8: 7. Hafta | AQ8: 7. Hafta | AR8: 7. Hafta | AS8: 7. Hafta | AT8: 7. Hafta | AU8: 7. Hafta | AV8: 7. Hafta | AW8: 8. Hafta | AX8: 8. Hafta | AY8: 8. Hafta | AZ8: 8. Hafta | BA8: 8. Hafta | BB8: 8. Hafta | BC8: 8. Hafta | BD8: 9. Hafta | BE8: 9. Hafta | BF8: 9. Hafta | BG8: 9. Hafta | BH8: 9. Hafta | BI8: 9. Hafta | BJ8: 9. Hafta | BK8: 10. Hafta | BL8: 10. Hafta | BM8: 10. Hafta | BN8: 10. Hafta | BO8: 10. Hafta | BP8: 10. Hafta | BQ8: 10. Hafta | BR8: 11. Hafta | BS8: 11. Hafta | BT8: 11. Hafta | BU8: 11. Hafta | BV8: 11. Hafta | BW8: 11. Hafta | BX8: 11. Hafta | BY8: 12. Hafta | BZ8: 12. Hafta | CA8: 12. Hafta | CB8: 12. Hafta | CC8: 12. Hafta | CD8: 12. Hafta | CE8: 12. Hafta | CF8: 13. Hafta | CG8: 13. Hafta | CH8: 13. Hafta | CI8: 13. Hafta | CJ8: 13. Hafta | CK8: 13. Hafta | CL8: 13. Hafta | CM8: 14. Hafta | CN8: 14. Hafta | CO8: 14. Hafta | CP8: 14. Hafta | CQ8: 14. Hafta | CR8: 14. Hafta | CS8: 14. Hafta | CT8: 15. Hafta | CU8: 15. Hafta | CV8: 15. Hafta | CW8: 15. Hafta | CX8: 15. Hafta | CY8: 15. Hafta | CZ8: 15. Hafta | DA8: 16. Hafta | DB8: 16. Hafta | DC8: 16. Hafta | DD8: 16. Hafta | DE8: 16. Hafta | DF8: 16. Hafta | DG8: 16. Hafta | DH8: 17. Hafta | DI8: 17. Hafta | DJ8: 17. Hafta | DK8: 17. Hafta | DL8: 17. Hafta | DM8: 17. Hafta | DN8: 17. Hafta | DO8: 18. Hafta | DP8: 18. Hafta | DQ8: 18. Hafta | DR8: 18. Hafta | DS8: 18. Hafta | DT8: 18. Hafta | DU8: 18. Hafta | DV8: 19. Hafta | DW8: 19. Hafta | DX8: 19. Hafta | DY8: 19. Hafta | DZ8: 19. Hafta | EA8: 19. Hafta | EB8: 19. Hafta | EC8: 20. Hafta | ED8: 20. Hafta | EE8: 20. Hafta | EF8: 20. Hafta | EG8: 20. Hafta | EH8: 20. Hafta | EI8: 20. Hafta | EJ8: 21. Hafta | EK8: 21. Hafta | EL8: 21. Hafta | EM8: 21. Hafta | EN8: 21. Hafta | EO8: 21. Hafta | EP8: 21. Hafta | EQ8: 22. Hafta | ER8: 22. Hafta | ES8: 22. Hafta | ET8: 22. Hafta | EU8: 22. Hafta | EV8: 22. Hafta | EW8: 22. Hafta | EX8: 23. Hafta | EY8: 23. Hafta | EZ8: 23. Hafta | FA8: 23. Hafta | FB8: 23. Hafta | FC8: 23. Hafta | FD8: 23. Hafta | FE8: 24. Hafta | FF8: 24. Hafta | FG8: 24. Hafta | FH8: 24. Hafta | FI8: 24. Hafta | FJ8: 24. Hafta | FK8: 24. Hafta | FL8: 25. Hafta | FM8: 25. Hafta | FN8: 25. Hafta | FO8: 25. Hafta | FP8: 25. Hafta | FQ8: 25. Hafta | FR8: 25. Hafta | FS8: 26. Hafta | FT8: 26. Hafta | FU8: 26. Hafta | FV8: 26. Hafta | FW8: 26. Hafta | FX8: 26. Hafta | FY8: 26. Hafta | FZ8: 27. Hafta | GA8: 27. Hafta | GB8: 27. Hafta | GC8: 27. Hafta | GD8: 27. Hafta | GE8: 27. Hafta | GF8: 27. Hafta | GG8: 28. Hafta | GH8: 28. Hafta | GI8: 28. Hafta | GJ8: 28. Hafta | GK8: 28. Hafta | GL8: 28. Hafta | GM8: 28. Hafta | GN8: 29. Hafta | GO8: 29. Hafta | GP8: 29. Hafta | GQ8: 29. Hafta | GR8: 29. Hafta | GS8: 29. Hafta | GT8: 29. Hafta | GU8: 30. Hafta | GV8: 30. Hafta | GW8: 30. Hafta | GX8: 30. Hafta | GY8: 30. Hafta | GZ8: 30. Hafta | HA8: 30. Hafta | HB8: 31. Hafta | HC8: 31. Hafta | HD8: 31. Hafta | HE8: 31. Hafta | HF8: 31. Hafta | HG8: 31. Hafta | HH8: 31. Hafta | HI8: 32. Hafta | HJ8: 32. Hafta | HK8: 32. Hafta | HL8: 32. Hafta | HM8: 32. Hafta | HN8: 32. Hafta | HO8: 32. Hafta | HP8: 33. Hafta | HQ8: 33. Hafta | HR8: 33. Hafta | HS8: 33. Hafta | HT8: 33. Hafta | HU8: 33. Hafta | HV8: 33. Hafta | HW8: 34. Hafta | HX8: 34. Hafta | HY8: 34. Hafta | HZ8: 34. Hafta | IA8: 34. Hafta | IB8: 34. Hafta | IC8: 34. Hafta | ID8: 35. Hafta | IE8: 35. Hafta | IF8: 35. Hafta | IG8: 35. Hafta | IH8: 35. Hafta | II8: 35. Hafta | IJ8: 35. Hafta | IK8: 36. Hafta | IL8: 36. Hafta | IM8: 36. Hafta | IN8: 36. Hafta | IO8: 36. Hafta | IP8: 36. Hafta | IQ8: 36. Hafta | IR8: 37. Hafta | IS8: 37. Hafta | IT8: 37. Hafta | IU8: 37. Hafta | IV8: 37. Hafta | IW8: 37. Hafta | IX8: 37. Hafta | IY8: 38. Hafta | IZ8: 38. Hafta | JA8: 38. Hafta | JB8: 38. Hafta | JC8: 38. Hafta | JD8: 38. Hafta | JE8: 38. Hafta | JF8: 39. Hafta | JG8: 39. Hafta | JH8: 39. Hafta | JI8: 39. Hafta | JJ8: 39. Hafta | JK8: 39. Hafta | JL8: 39. Hafta | JM8: 40. Hafta | JN8: 40. Hafta | JO8: 40. Hafta | JP8: 40. Hafta | JQ8: 40. Hafta | JR8: 40. Hafta | JS8: 40. Hafta | JT8: 41. Hafta | JU8: 41. Hafta | JV8: 41. Hafta | JW8: 41. Hafta | JX8: 41. Hafta | JY8: 41. Hafta | JZ8: 41. Hafta
A9: =+SUM(C9:NC9) -> 1114121.5 | B9: Gerçekleşen Çalışma Saat | D9: 3894.9167 | E9: 3848.5 | G9: 3985.1667 | H9: 4219.8333 | I9: 4204.0833 | J9: 4224.8333 | K9: 3975 | L9: 3399.4167 | N9: 3994.0449 | O9: 4176.8138 | P9: 3613.8608 | Q9: 4025.0435 | R9: 4074.1878 | S9: 4038.1995 | U9: 3709.6667 | V9: 4002.25 | W9: 4010.4167 | X9: 4018.3333 | Y9: 4020.75 | Z9: 3871.4167 | AB9: 3907.6667 | AC9: 3993.8333 | AD9: 4189.625 | AE9: 3994.7917 | AF9: 3845.4583 | AG9: 3867.6667 | AI9: 4194.25 | AJ9: 4099 | AK9: 4026.0833 | AL9: 4044.25 | AM9: 4067.3333 | AN9: 3770.3333 | AP9: 4069.4167 | AQ9: 4067.6667 | AR9: 4065.75 | AS9: 3993.6667 | AT9: 4095.6667 | AU9: 3879.3333 | AW9: 4073.4167 | AX9: 4139.5833 | AY9: 4062.3333 | AZ9: 3993.6667 | BA9: 3934.25 | BB9: 4040.3333 | BD9: 3987.5 | BE9: 4035.9167 | BF9: 4126.8333 | BG9: 4117.25 | BH9: 4422.9167 | BI9: 4088.8333 | BK9: 5709.9167 | BL9: 5618.75 | BM9: 4850.3333 | BN9: 4671.75 | BO9: 4645.75 | BP9: 5114.25 | BR9: 5787.25 | BS9: 5950.0833 | BT9: 6018.8333 | BU9: 5827.5 | BV9: 5880 | BW9: 5520.4167 | BX9: 4250.25 | BY9: 5287.1667 | BZ9: 4290.6667 | CA9: 4149.4167 | CB9: 1315 | CF9: 4476.9167 | CG9: 4569.25 | CH9: 4595 | CI9: 4358.75 | CJ9: 4002.3333 | CK9: 3928.9167 | CM9: 4098.75 | CN9: 4021.0833 | CO9: 3995.6667 | CP9: 4143.75 | CQ9: 4136.5833 | CR9: 3467.6667 | CT9: 4392.75 | CU9: 4303.3333 | CV9: 4470.25 | CW9: 4571.0833 | CX9: 4292.3333 | CY9: 3895.9167 | DA9: 4031.5833 | DB9: 4157 | DC9: 3984.25 | DD9: 3986.25 | DE9: 4091.9167 | DF9: 3992 | DG9: 3433.6667 | DH9: 3939.5833 | DI9: 4202.4167 | DJ9: 4359.25 | DK9: 3953.75 | DL9: 3878.9167 | DM9: 3654.0833 | DO9: 3771.75 | DP9: 3999.0833 | DQ9: 3949.4167 | DR9: 3895.9167 | DT9: 3838.4167 | DU9: 3527.3333 | DV9: 3744 | DW9: 4384.0833 | DX9: 4321.9167 | DY9: 4123.4167 | DZ9: 4280 | EA9: 3688.9167 | EC9: 4982.8333 | ED9: 4993.25 | EE9: 5049.1667 | EF9: 5281.6667 | EG9: 5230.0833 | EH9: 5227.4167 | EI9: 5229.1667 | EJ9: 5407.3333 | EK9: 5060.75 | EL9: 5457.3333 | EM9: 5177.0833 | EN9: 4890.25 | EO9: 4760 | EQ9: 4302 | ER9: 1374.25 | EV9: 4147.3333 | EX9: 4264.1667 | EY9: 4715.3333 | EZ9: 4665.3333 | FA9: 4471.5 | FB9: 4616.25 | FC9: 4117.9167 | FE9: 4377.9167 | FF9: 4546.25 | FG9: 4577.6667 | FH9: 4719.3333 | FI9: 5170.4917 | FJ9: 4566.0833 | FK9: 3474.5833 | FL9: 4445.5833 | FM9: 4607.1667 | FN9: 4292.9167 | FO9: 4036.4167 | FP9: 4083.1667 | FQ9: 3508.3333 | FS9: 4200.6667 | FT9: 4464 | FU9: 4374.4167 | FV9: 4474.5 | FW9: 4376.5 | FX9: 4115.25 | FY9: 3194.9167 | FZ9: 4242.25 | GA9: 4267.6667 | GB9: 4361.6667 | GC9: 4539 | GD9: 4403.5833 | GE9: 4091.0833 | GG9: 4140.4167 | GH9: 4631.3333 | GI9: 4707.9167 | GJ9: 4668.1667 | GK9: 4529.5833 | GL9: 4054.8333 | GM9: 3522.9167 | GN9: 3992.3333 | GO9: 3854.5 | GP9: 3695.6667 | GQ9: 3932.3333 | GR9: 3982.3333 | GS9: 3536.8333 | GU9: 4075.5 | GV9: 4075.5833 | GW9: 4074.8333 | GX9: 4095.4167 | GY9: 4170.3333 | GZ9: 3876.9167 | HA9: 3248.8333 | HB9: 3986.3333 | HC9: 4195.5 | HD9: 4133.6667 | HE9: 4335.8333 | HF9: 4404 | HG9: 4249.6667 | HI9: 4163.1667 | HJ9: 4161.5833 | HK9: 4247.0833 | HL9: 4324.5833 | HM9: 4201.5833 | HN9: 4041 | HO9: 3121.5 | HP9: 4342 | HQ9: 4616.9167 | HR9: 4954.6667 | HS9: 5170 | HT9: 5472.25 | HU9: 5061.1667 | HW9: 5473.0833 | HX9: 5154 | HY9: 5262.1667 | HZ9: 5225.5 | IA9: 5147.75 | IB9: 4747 | IC9: 3675 | ID9: 4432.5833 | IE9: 4648 | IF9: 4772.25 | IG9: 4871.25 | IH9: 4537.6667 | II9: 4252.4167 | IK9: 4458.5 | IL9: 4659.75 | IM9: 4909.4167 | IN9: 5583 | IO9: 5203.1667 | IP9: 4913.1667 | IQ9: 3596.5 | IR9: 5348.0833 | IS9: 5503.4167 | IT9: 5608.5 | IU9: 5374.4167 | IV9: 5515.5833 | IW9: 4944.3333 | IY9: 5840.6667 | IZ9: 5829.9167 | JA9: 5765.3333 | JB9: 6059.6667 | JC9: 5897.8333 | JD9: 5750.0833 | JF9: 5767.0833 | JG9: 5695.9167 | JH9: 6156.4167 | JI9: 6094.5 | JJ9: 6185.25 | JK9: 5946 | JM9: 6249.9167 | JN9: 6313 | JO9: 6446.5 | JP9: 6467.8333 | JQ9: 6340.0833 | JR9: 5774.6667 | JT9: 6522.3333 | JU9: 6602.3333 | JV9: 6567.3333 | JW9: 6539.25 | JX9: 6319.75 | JY9: 5894.5
A10: =+SUM(C10:NC10) -> 39691639 | B10: Gerçekleşen Adet | D10: 164483 | E10: 162693 | G10: 134660 | H10: 147684 | I10: 173938 | J10: 182336 | K10: 143853 | L10: 129090 | N10: 146301 | O10: 137664 | P10: 167516 | Q10: 150454 | R10: 116979 | S10: 109338 | U10: 128127 | V10: 131650 | W10: 137273 | X10: 132714 | Y10: 168501 | Z10: 140943 | AB10: 137982 | AC10: 144881 | AD10: 179820 | AE10: 160514 | AF10: 102208 | AG10: 97072 | AI10: 123248 | AJ10: 142502 | AK10: 118768 | AL10: 153940 | AM10: 137928 | AN10: 77314 | AP10: 131983 | AQ10: 136092 | AR10: 144175 | AS10: 112178 | AT10: 102963 | AU10: 98509 | AW10: 124046 | AX10: 126422 | AY10: 142892 | AZ10: 130156 | BA10: 138303 | BB10: 135570 | BD10: 139111 | BE10: 154719 | BF10: 170958 | BG10: 171665 | BH10: 165417 | BI10: 143140 | BK10: 170506 | BL10: 200581 | BM10: 187064 | BN10: 171305 | BO10: 161416 | BP10: 188394 | BR10: 204914 | BS10: 225421 | BT10: 227633 | BU10: 240083 | BV10: 236877 | BW10: 226868 | BX10: 161107 | BY10: 196826 | BZ10: 183886 | CA10: 129772 | CB10: 23290 | CF10: 140064 | CG10: 194351 | CH10: 197964 | CI10: 178113 | CJ10: 152426 | CK10: 146438 | CM10: 137391 | CN10: 150863 | CO10: 166578 | CP10: 157347 | CQ10: 156080 | CR10: 126619 | CT10: 141815 | CU10: 142688 | CV10: 173757 | CW10: 180019 | CX10: 159246 | CY10: 156817 | DA10: 134647 | DB10: 144859 | DC10: 158487 | DD10: 159831 | DE10: 159905 | DF10: 165381 | DG10: 162633 | DH10: 139615 | DI10: 172042 | DJ10: 185298 | DK10: 190087 | DL10: 143120 | DM10: 109755 | DO10: 140579 | DP10: 152369 | DQ10: 162660 | DR10: 163354 | DT10: 157855 | DU10: 161947 | DV10: 146189 | DW10: 165619 | DX10: 180758 | DY10: 185689 | DZ10: 156073 | EA10: 173745 | EC10: 186558 | ED10: 198380 | EE10: 206610 | EF10: 214239 | EG10: 189470 | EH10: 215173 | EI10: 227177 | EJ10: 213725 | EK10: 213273 | EL10: 208345 | EM10: 220286 | EN10: 222436 | EO10: 227296 | EQ10: 161649 | ER10: 50260 | EV10: 151872 | EX10: 166644 | EY10: 189569 | EZ10: 189106 | FA10: 181150 | FB10: 183620 | FC10: 172881 | FE10: 169602 | FF10: 174047 | FG10: 188469 | FH10: 194652 | FI10: 181625 | FJ10: 193580 | FK10: 160524 | FL10: 160778 | FM10: 167775 | FN10: 175553 | FO10: 173585 | FP10: 169932 | FQ10: 156860 | FS10: 148356 | FT10: 179655 | FU10: 163397 | FV10: 170350 | FW10: 155389 | FX10: 169485 | FY10: 150959 | FZ10: 161920 | GA10: 189186 | GB10: 174062 | GC10: 154137 | GD10: 138736 | GE10: 146611 | GG10: 148002 | GH10: 164947 | GI10: 124543 | GJ10: 132064 | GK10: 175907 | GL10: 143468 | GM10: 128818 | GN10: 150969 | GO10: 132618 | GP10: 142055 | GQ10: 143815 | GR10: 144625 | GS10: 131045 | GU10: 131888 | GV10: 133648 | GW10: 147108 | GX10: 155842 | GY10: 140157 | GZ10: 144687 | HA10: 118866 | HB10: 136140 | HC10: 129830 | HD10: 146201 | HE10: 136909 | HF10: 139121 | HG10: 131146 | HI10: 134306 | HJ10: 124051 | HK10: 149622 | HL10: 155809 | HM10: 146082 | HN10: 149623 | HO10: 120912 | HP10: 134438 | HQ10: 145103 | HR10: 149963 | HS10: 178642 | HT10: 167111 | HU10: 159734 | HW10: 197899 | HX10: 185783 | HY10: 173162 | HZ10: 141167 | IA10: 184301 | IB10: 173854 | IC10: 147005 | ID10: 131016 | IE10: 154550 | IF10: 143398 | IG10: 126968 | IH10: 162136 | II10: 151488 | IK10: 119742 | IL10: 149154 | IM10: 181767 | IN10: 122468 | IO10: 126423 | IP10: 136542 | IQ10: 123563 | IR10: 168735 | IS10: 170068 | IT10: 163215 | IU10: 175868 | IV10: 180183 | IW10: 180638 | IY10: 177337 | IZ10: 184428 | JA10: 206432 | JB10: 173620 | JC10: 197019 | JD10: 204336 | JF10: 231763 | JG10: 161496 | JH10: 187278 | JI10: 185131 | JJ10: 177559 | JK10: 209947 | JM10: 190901 | JN10: 187295 | JO10: 188441 | JP10: 188648 | JQ10: 169036 | JR10: 245071 | JT10: 194267 | JU10: 201650 | JV10: 185079 | JW10: 185179 | JX10: 198266 | JY10: 143919
A11: =+A10/A9 -> 35.625951 | B11: Gerçekleşen Verimlilik | C11: =+IFERROR(C10/C9,"") | D11: =+IFERROR(D10/D9,"") -> 42.230172 | E11: =+IFERROR(E10/E9,"") -> 42.274393 | G11: =+IFERROR(G10/G9,"") -> 33.790306 | H11: =+IFERROR(H10/H9,"") -> 34.997591 | I11: =+IFERROR(I10/I9,"") -> 41.373585 | J11: =+IFERROR(J10/J9,"") -> 43.158152 | K11: =+IFERROR(K10/K9,"") -> 36.189434 | L11: =+IFERROR(L10/L9,"") -> 37.974162 | N11: =+IFERROR(N10/N9,"") -> 36.629783 | O11: =+IFERROR(O10/O9,"") -> 32.959094 | P11: =+IFERROR(P10/P9,"") -> 46.35375 | Q11: =+IFERROR(Q10/Q9,"") -> 37.379471 | R11: =+IFERROR(R10/R9,"") -> 28.712226 | S11: =+IFERROR(S10/S9,"") -> 27.075928 | T11: =+IFERROR(T10/T9,"") | U11: =+IFERROR(U10/U9,"") -> 34.538683 | ... ER11: =+IFERROR(ER10/ER9,"") -> 36.572676 | EV11: =+IFERROR(EV10/EV9,"") -> 36.619193 | EW11: =+IFERROR(EW10/EW9,"") | EX11: =+IFERROR(EX10/EX9,"") -> 39.080086 | EY11: =+IFERROR(EY10/EY9,"") -> 40.202672 | EZ11: =+IFERROR(EZ10/EZ9,"") -> 40.534296 | FA11: =+IFERROR(FA10/FA9,"") -> 40.512132 | FB11: =+IFERROR(FB10/FB9,"") -> 39.776875 | FC11: =+IFERROR(FC10/FC9,"") -> 41.982637 | ... JZ11: =+IFERROR(JZ10/JZ9,"")

Sheet Genel Müşteri Çıkış
A1: Toplam | B1: Tarih | C1: 45658 | D1: 45659 | E1: 45660 | F1: 45661 | G1: 45662 | H1: 45663 | I1: 45664 | J1: 45665 | K1: 45666 | L1: 45667 | M1: 45668 | N1: 45669 | O1: 45670 | P1: 45671 | Q1: 45672 | R1: 45673 | S1: 45674 | T1: 45675 | U1: 45676 | V1: 45677 | W1: 45678 | X1: 45679 | Y1: 45680 | Z1: 45681 | AA1: 45682 | AB1: 45683 | AC1: 45684 | AD1: 45685 | AE1: 45686 | AF1: 45687 | AG1: 45688 | AH1: 45689 | AI1: 45690 | AJ1: 45691 | AK1: 45692 | AL1: 45693 | AM1: 45694 | AN1: 45695 | AO1: 45696 | AP1: 45697 | AQ1: 45698 | AR1: 45699 | AS1: 45700 | AT1: 45701 | AU1: 45702 | AV1: 45703 | AW1: 45704 | AX1: 45705 | AY1: 45706 | AZ1: 45707 | BA1: 45708 | BB1: 45709 | BC1: 45710 | BD1: 45711 | BE1: 45712 | BF1: 45713 | BG1: 45714 | BH1: 45715 | BI1: 45716 | BJ1: 45717 | BK1: 45718 | BL1: 45719 | BM1: 45720 | BN1: 45721 | BO1: 45722 | BP1: 45723 | BQ1: 45724 | BR1: 45725 | BS1: 45726 | BT1: 45727 | BU1: 45728 | BV1: 45729 | BW1: 45730 | BX1: 45731 | BY1: 45732 | BZ1: 45733 | CA1: 45734 | CB1: 45735 | CC1: 45736 | CD1: 45737 | CE1: 45738 | CF1: 45739 | CG1: 45740 | CH1: 45741 | CI1: 45742 | CJ1: 45743 | CK1: 45744 | CL1: 45745 | CM1: 45746 | CN1: 45747 | CO1: 45748 | CP1: 45749 | CQ1: 45750 | CR1: 45751 | CS1: 45752 | CT1: 45753 | CU1: 45754 | CV1: 45755 | CW1: 45756 | CX1: 45757 | CY1: 45758 | CZ1: 45759 | DA1: 45760 | DB1: 45761 | DC1: 45762 | DD1: 45763 | DE1: 45764 | DF1: 45765 | DG1: 45766 | DH1: 45767 | DI1: 45768 | DJ1: 45769 | DK1: 45770 | DL1: 45771 | DM1: 45772 | DN1: 45773 | DO1: 45774 | DP1: 45775 | DQ1: 45776 | DR1: 45777 | DS1: 45778 | DT1: 45779 | DU1: 45780 | DV1: 45781 | DW1: 45782 | DX1: 45783 | DY1: 45784 | DZ1: 45785 | EA1: 45786 | EB1: 45787 | EC1: 45788 | ED1: 45789 | EE1: 45790 | EF1: 45791 | EG1: 45792 | EH1: 45793 | EI1: 45794 | EJ1: 45795 | EK1: 45796 | EL1: 45797 | EM1: 45798 | EN1: 45799 | EO1: 45800 | EP1: 45801 | EQ1: 45802 | ER1: 45803 | ES1: 45804 | ET1: 45805 | EU1: 45806 | EV1: 45807 | EW1: 45808 | EX1: 45809 | EY1: 45810 | EZ1: 45811 | FA1: 45812 | FB1: 45813 | FC1: 45814 | FD1: 45815 | FE1: 45816 | FF1: 45817 | FG1: 45818 | FH1: 45819 | FI1: 45820 | FJ1: 45821 | FK1: 45822 | FL1: 45823 | FM1: 45824 | FN1: 45825 | FO1: 45826 | FP1: 45827 | FQ1: 45828 | FR1: 45829 | FS1: 45830 | FT1: 45831 | FU1: 45832 | FV1: 45833 | FW1: 45834 | FX1: 45835 | FY1: 45836 | FZ1: 45837 | GA1: 45838 | GB1: 45839 | GC1: 45840 | GD1: 45841 | GE1: 45842 | GF1: 45843 | GG1: 45844 | GH1: 45845 | GI1: 45846 | GJ1: 45847 | GK1: 45848 | GL1: 45849 | GM1: 45850 | GN1: 45851 | GO1: 45852 | GP1: 45853 | GQ1: 45854 | GR1: 45855 | GS1: 45856 | GT1: 45857 | GU1: 45858 | GV1: 45859 | GW1: 45860 | GX1: 45861 | GY1: 45862 | GZ1: 45863 | HA1: 45864 | HB1: 45865 | HC1: 45866 | HD1: 45867 | HE1: 45868 | HF1: 45869 | HG1: 45870 | HH1: 45871 | HI1: 45872 | HJ1: 45873 | HK1: 45874 | HL1: 45875 | HM1: 45876 | HN1: 45877 | HO1: 45878 | HP1: 45879 | HQ1: 45880 | HR1: 45881 | HS1: 45882 | HT1: 45883 | HU1: 45884 | HV1: 45885 | HW1: 45886 | HX1: 45887 | HY1: 45888 | HZ1: 45889 | IA1: 45890 | IB1: 45891 | IC1: 45892 | ID1: 45893 | IE1: 45894 | IF1: 45895 | IG1: 45896 | IH1: 45897 | II1: 45898 | IJ1: 45899 | IK1: 45900 | IL1: 45901 | IM1: 45902 | IN1: 45903 | IO1: 45904 | IP1: 45905 | IQ1: 45906 | IR1: 45907 | IS1: 45908 | IT1: 45909 | IU1: 45910 | IV1: 45911 | IW1: 45912 | IX1: 45913 | IY1: 45914 | IZ1: 45915 | JA1: 45916 | JB1: 45917 | JC1: 45918 | JD1: 45919 | JE1: 45920 | JF1: 45921 | JG1: 45922 | JH1: 45923 | JI1: 45924 | JJ1: 45925 | JK1: 45926 | JL1: 45927 | JM1: 45928 | JN1: 45929 | JO1: 45930 | JP1: 45931 | JQ1: 45932 | JR1: 45933 | JS1: 45934 | JT1: 45935 | JU1: 45936 | JV1: 45937 | JW1: 45938 | JX1: 45939 | JY1: 45940 | JZ1: 45941 | KA1: 45942 | KB1: 45943 | KC1: 45944 | KD1: 45945 | KE1: 45946 | KF1: 45947 | KG1: 45948 | KH1: 45949 | KI1: 45950 | KJ1: 45951 | KK1: 45952 | KL1: 45953 | KM1: 45954 | KN1: 45955 | KO1: 45956 | KP1: 45957 | KQ1: 45958 | KR1: 45959 | KS1: 45960 | KT1: 45961 | KU1: 45962 | KV1: 45963 | KW1: 45964 | KX1: 45965 | KY1: 45966 | KZ1: 45967 | LA1: 45968 | LB1: 45969 | LC1: 45970 | LD1: 45971 | LE1: 45972 | LF1: 45973 | LG1: 45974 | LH1: 45975 | LI1: 45976 | LJ1: 45977 | LK1: 45978 | LL1: 45979 | LM1: 45980 | LN1: 45981 | LO1: 45982 | LP1: 45983 | LQ1: 45984 | LR1: 45985 | LS1: 45986 | LT1: 45987 | LU1: 45988 | LV1: 45989 | LW1: 45990 | LX1: 45991 | LY1: 45992 | LZ1: 45993 | MA1: 45994 | MB1: 45995 | MC1: 45996 | MD1: 45997 | ME1: 45998 | MF1: 45999 | MG1: 46000 | MH1: 46001 | MI1: 46002 | MJ1: 46003 | MK1: 46004 | ML1: 46005 | MM1: 46006 | MN1: 46007 | MO1: 46008 | MP1: 46009 | MQ1: 46010 | MR1: 46011 | MS1: 46012 | MT1: 46013 | MU1: 46014 | MV1: 46015 | MW1: 46016 | MX1: 46017 | MY1: 46018 | MZ1: 46019 | NA1: 46020 | NB1: 46021 | NC1: 46022
B2: Hafta | C2: 1. Hafta | D2: 1. Hafta | E2: 1. Hafta | F2: 1. Hafta | G2: 1. Hafta | H2: 2. Hafta | I2: 2. Hafta | J2: 2. Hafta | K2: 2. Hafta | L2: 2. Hafta | M2: 2. Hafta | N2: 2. Hafta | O2: 3. Hafta | P2: 3. Hafta | Q2: 3. Hafta | R2: 3. Hafta | S2: 3. Hafta | T2: 3. Hafta | U2: 3. Hafta | V2: 4. Hafta | W2: 4. Hafta | X2: 4. Hafta | Y2: 4. Hafta | Z2: 4. Hafta | AA2: 4. Hafta | AB2: 4. Hafta | AC2: 5. Hafta | AD2: 5. Hafta | AE2: 5. Hafta | AF2: 5. Hafta | AG2: 5. Hafta | AH2: 5. Hafta | AI2: 5. Hafta | AJ2: 6. Hafta | AK2: 6. Hafta | AL2: 6. Hafta | AM2: 6. Hafta | AN2: 6. Hafta | AO2: 6. Hafta | AP2: 6. Hafta | AQ2: 7. Hafta | AR2: 7. Hafta | AS2: 7. Hafta | AT2: 7. Hafta | AU2: 7. Hafta | AV2: 7. Hafta | AW2: 7. Hafta | AX2: 8. Hafta | AY2: 8. Hafta | AZ2: 8. Hafta | BA2: 8. Hafta | BB2: 8. Hafta | BC2: 8. Hafta | BD2: 8. Hafta | BE2: 9. Hafta | BF2: 9. Hafta | BG2: 9. Hafta | BH2: 9. Hafta | BI2: 9. Hafta | BJ2: 9. Hafta | BK2: 9. Hafta | BL2: 10. Hafta | BM2: 10. Hafta | BN2: 10. Hafta | BO2: 10. Hafta | BP2: 10. Hafta | BQ2: 10. Hafta | BR2: 10. Hafta | BS2: 11. Hafta | BT2: 11. Hafta | BU2: 11. Hafta | BV2: 11. Hafta | BW2: 11. Hafta | BX2: 11. Hafta | BY2: 11. Hafta | BZ2: 12. Hafta | CA2: 12. Hafta | CB2: 12. Hafta | CC2: 12. Hafta | CD2: 12. Hafta | CE2: 12. Hafta | CF2: 12. Hafta | CG2: 13. Hafta | CH2: 13. Hafta | CI2: 13. Hafta | CJ2: 13. Hafta | CK2: 13. Hafta | CL2: 13. Hafta | CM2: 13. Hafta | CN2: 14. Hafta | CO2: 14. Hafta | CP2: 14. Hafta | CQ2: 14. Hafta | CR2: 14. Hafta | CS2: 14. Hafta | CT2: 14. Hafta | CU2: 15. Hafta | CV2: 15. Hafta | CW2: 15. Hafta | CX2: 15. Hafta | CY2: 15. Hafta | CZ2: 15. Hafta | DA2: 15. Hafta | DB2: 16. Hafta | DC2: 16. Hafta | DD2: 16. Hafta | DE2: 16. Hafta | DF2: 16. Hafta | DG2: 16. Hafta | DH2: 16. Hafta | DI2: 17. Hafta | DJ2: 17. Hafta | DK2: 17. Hafta | DL2: 17. Hafta | DM2: 17. Hafta | DN2: 17. Hafta | DO2: 17. Hafta | DP2: 18. Hafta | DQ2: 18. Hafta | DR2: 18. Hafta | DS2: 18. Hafta | DT2: 18. Hafta | DU2: 18. Hafta | DV2: 18. Hafta | DW2: 19. Hafta | DX2: 19. Hafta | DY2: 19. Hafta | DZ2: 19. Hafta | EA2: 19. Hafta | EB2: 19. Hafta | EC2: 19. Hafta | ED2: 20. Hafta | EE2: 20. Hafta | EF2: 20. Hafta | EG2: 20. Hafta | EH2: 20. Hafta | EI2: 20. Hafta | EJ2: 20. Hafta | EK2: 21. Hafta | EL2: 21. Hafta | EM2: 21. Hafta | EN2: 21. Hafta | EO2: 21. Hafta | EP2: 21. Hafta | EQ2: 21. Hafta | ER2: 22. Hafta | ES2: 22. Hafta | ET2: 22. Hafta | EU2: 22. Hafta | EV2: 22. Hafta | EW2: 22. Hafta | EX2: 22. Hafta | EY2: 23. Hafta | EZ2: 23. Hafta | FA2: 23. Hafta | FB2: 23. Hafta | FC2: 23. Hafta | FD2: 23. Hafta | FE2: 23. Hafta | FF2: 24. Hafta | FG2: 24. Hafta | FH2: 24. Hafta | FI2: 24. Hafta | FJ2: 24. Hafta | FK2: 24. Hafta | FL2: 24. Hafta | FM2: 25. Hafta | FN2: 25. Hafta | FO2: 25. Hafta | FP2: 25. Hafta | FQ2: 25. Hafta | FR2: 25. Hafta | FS2: 25. Hafta | FT2: 26. Hafta | FU2: 26. Hafta | FV2: 26. Hafta | FW2: 26. Hafta | FX2: 26. Hafta | FY2: 26. Hafta | FZ2: 26. Hafta | GA2: 27. Hafta | GB2: 27. Hafta | GC2: 27. Hafta | GD2: 27. Hafta | GE2: 27. Hafta | GF2: 27. Hafta | GG2: 27. Hafta | GH2: 28. Hafta | GI2: 28. Hafta | GJ2: 28. Hafta | GK2: 28. Hafta | GL2: 28. Hafta | GM2: 28. Hafta | GN2: 28. Hafta | GO2: 29. Hafta | GP2: 29. Hafta | GQ2: 29. Hafta | GR2: 29. Hafta | GS2: 29. Hafta | GT2: 29. Hafta | GU2: 29. Hafta | GV2: 30. Hafta | GW2: 30. Hafta | GX2: 30. Hafta | GY2: 30. Hafta | GZ2: 30. Hafta | HA2: 30. Hafta | HB2: 30. Hafta | HC2: 31. Hafta | HD2: 31. Hafta | HE2: 31. Hafta | HF2: 31. Hafta | HG2: 31. Hafta | HH2: 31. Hafta | HI2: 31. Hafta | HJ2: 32. Hafta | HK2: 32. Hafta | HL2: 32. Hafta | HM2: 32. Hafta | HN2: 32. Hafta | HO2: 32. Hafta | HP2: 32. Hafta | HQ2: 33. Hafta | HR2: 33. Hafta | HS2: 33. Hafta | HT2: 33. Hafta | HU2: 33. Hafta | HV2: 33. Hafta | HW2: 33. Hafta | HX2: 34. Hafta | HY2: 34. Hafta | HZ2: 34. Hafta | IA2: 34. Hafta | IB2: 34. Hafta | IC2: 34. Hafta | ID2: 34. Hafta | IE2: 35. Hafta | IF2: 35. Hafta | IG2: 35. Hafta | IH2: 35. Hafta | II2: 35. Hafta | IJ2: 35. Hafta | IK2: 35. Hafta | IL2: 36. Hafta | IM2: 36. Hafta | IN2: 36. Hafta | IO2: 36. Hafta | IP2: 36. Hafta | IQ2: 36. Hafta | IR2: 36. Hafta | IS2: 37. Hafta | IT2: 37. Hafta | IU2: 37. Hafta | IV2: 37. Hafta | IW2: 37. Hafta | IX2: 37. Hafta | IY2: 37. Hafta | IZ2: 38. Hafta | JA2: 38. Hafta | JB2: 38. Hafta | JC2: 38. Hafta | JD2: 38. Hafta | JE2: 38. Hafta | JF2: 38. Hafta | JG2: 39. Hafta | JH2: 39. Hafta | JI2: 39. Hafta | JJ2: 39. Hafta | JK2: 39. Hafta | JL2: 39. Hafta | JM2: 39. Hafta | JN2: 40. Hafta | JO2: 40. Hafta | JP2: 40. Hafta | JQ2: 40. Hafta | JR2: 40. Hafta | JS2: 40. Hafta | JT2: 40. Hafta | JU2: 41. Hafta | JV2: 41. Hafta | JW2: 41. Hafta | JX2: 41. Hafta | JY2: 41. Hafta | JZ2: 41. Hafta | KA2: 41. Hafta | KB2: 42. Hafta | KC2: 42. Hafta | KD2: 42. Hafta | KE2: 42. Hafta | KF2: 42. Hafta | KG2: 42. Hafta | KH2: 42. Hafta | KI2: 43. Hafta | KJ2: 43. Hafta | KK2: 43. Hafta | KL2: 43. Hafta | KM2: 43. Hafta | KN2: 43. Hafta | KO2: 43. Hafta | KP2: 44. Hafta | KQ2: 44. Hafta | KR2: 44. Hafta | KS2: 44. Hafta | KT2: 44. Hafta | KU2: 44. Hafta | KV2: 44. Hafta | KW2: 45. Hafta | KX2: 45. Hafta | KY2: 45. Hafta | KZ2: 45. Hafta | LA2: 45. Hafta | LB2: 45. Hafta | LC2: 45. Hafta | LD2: 46. Hafta | LE2: 46. Hafta | LF2: 46. Hafta | LG2: 46. Hafta | LH2: 46. Hafta | LI2: 46. Hafta | LJ2: 46. Hafta | LK2: 47. Hafta | LL2: 47. Hafta | LM2: 47. Hafta | LN2: 47. Hafta | LO2: 47. Hafta | LP2: 47. Hafta | LQ2: 47. Hafta | LR2: 48. Hafta | LS2: 48. Hafta | LT2: 48. Hafta | LU2: 48. Hafta | LV2: 48. Hafta | LW2: 48. Hafta | LX2: 48. Hafta | LY2: 49. Hafta | LZ2: 49. Hafta | MA2: 49. Hafta | MB2: 49. Hafta | MC2: 49. Hafta | MD2: 49. Hafta | ME2: 49. Hafta | MF2: 50. Hafta | MG2: 50. Hafta | MH2: 50. Hafta | MI2: 50. Hafta | MJ2: 50. Hafta | MK2: 50. Hafta | ML2: 50. Hafta | MM2: 51. Hafta | MN2: 51. Hafta | MO2: 51. Hafta | MP2: 51. Hafta | MQ2: 51. Hafta | MR2: 51. Hafta | MS2: 51. Hafta | MT2: 52. Hafta | MU2: 52. Hafta | MV2: 52. Hafta | MW2: 52. Hafta | MX2: 52. Hafta | MY2: 52. Hafta | MZ2: 52. Hafta | NA2: 1. Hafta | NB2: 1. Hafta | NC2: 1. Hafta
A3: =+SUM(C3:NC3) -> 1218157.4 | B3: Gerçekleşen Çalışma Saat | D3: 3621.0173 | E3: 3263.6042 | F3: 2147.1162 | G3: 1772.3832 | H3: 3482.0503 | I3: 2988.405 | J3: 2232.5113 | K3: 2324.7807 | L3: 2604.9691 | M3: 1857.5806 | N3: 1762.3825 | O3: 2897.9511 | P3: 3124.7371 | Q3: 3172.5272 | R3: 3004.832 | S3: 3046.2001 | T3: 2009.1729 | U3: 1714.2858 | V3: 3403.0471 | W3: 3170.3119 | X3: 3114.4103 | Y3: 2729.1409 | Z3: 2989.9247 | AA3: 2017.9015 | AB3: 1791.3086 | AC3: 2813.1901 | AD3: 2602.328 | AE3: 2580.2292 | AF3: 2768.9235 | AG3: 2577.4969 | AH3: 1816.2008 | AI3: 1699.5995 | AJ3: 2496.2047 | AK3: 2612.6239 | AL3: 3133.2093 | AM3: 2917.9614 | AN3: 2913.3351 | AO3: 1647.1134 | AP3: 1537.7302 | AQ3: 2818.9635 | AR3: 3433.2649 | AS3: 3198.2302 | AT3: 3013.3969 | AU3: 2451.597 | AV3: 1320.1256 | AW3: 1518.2244 | AX3: 2956.4051 | AY3: 3099.4948 | AZ3: 2795.2685 | BA3: 2834.4719 | BB3: 2514.4711 | BC3: 849.09767 | BD3: 1064.2261 | BE3: 3218.5962 | BF3: 2987.1307 | BG3: 3000.4212 | BH3: 2571.4574 | BI3: 2527.6985 | BJ3: 1383.5858 | BK3: 727.94642 | BL3: 2827.3836 | BM3: 2754.1657 | BN3: 2622.711 | BO3: 2687.8224 | BP3: 2981.1264 | BQ3: 2635.9182 | BR3: 1481.0789 | BS3: 4318.5125 | BT3: 3884.2038 | BU3: 3771.1459 | BV3: 3926.5707 | BW3: 3583.6738 | BX3: 2535.6515 | BY3: 1406.5878 | BZ3: 4711.1766 | CA3: 5184.5334 | CB3: 4973.5816 | CC3: 5102.7157 | CD3: 5146.0588 | CE3: 4421.6606 | CF3: 4353.2746 | CG3: 5206.6801 | CH3: 5189.9157 | CI3: 4078.3605 | CJ3: 3162.3721 | CK3: 3123.7565 | CL3: 864.57546 | CP3: 2773.5195 | CQ3: 3567.6655 | CR3: 3086.2088 | CS3: 1996.1275 | CT3: 1757.3353 | CU3: 2953.648 | CV3: 2909.223 | CW3: 2717.5718 | CX3: 2919.8758 | CY3: 3067.3273 | CZ3: 1884.2126 | DA3: 1465.3023 | DB3: 3209.8282 | DC3: 3744.7691 | DD3: 3439.6688 | DE3: 3058.7861 | DF3: 3139.4872 | DG3: 1889.341 | DH3: 1894.7135 | DI3: 3630.3949 | DJ3: 3244.4376 | DK3: 647.21665 | DM3: 4316.4698 | DN3: 3877.8795 | DO3: 2879.7034 | DP3: 2893.4928 | DQ3: 2932.1624 | DR3: 3265.5197 | DT3: 3967.7406 | DU3: 2632.7996 | DV3: 1274.0635 | DW3: 3909.6548 | DX3: 4044.3929 | DY3: 4212.1033 | DZ3: 4146.9223 | EA3: 4168.6939 | EB3: 2536.6485 | EC3: 1335.9566 | ED3: 4952.9426 | EE3: 4534.0583 | EF3: 4481.4097 | EG3: 4264.5358 | EH3: 4256.3728 | EI3: 2654.2609 | EJ3: 1408.0914 | EK3: 5248.1184 | EL3: 4808.8674 | EM3: 5203.8508 | EN3: 4824.4803 | EO3: 4392.4814 | EP3: 3864.0777 | EQ3: 1543.4368 | ER3: 5300.9989 | ES3: 5452.1275 | ET3: 5413.7013 | EU3: 5455.3432 | EV3: 5377.8547 | EW3: 5627.0264 | EX3: 4569.9079 | EY3: 4396.4125 | EZ3: 3900.1567 | FA3: 3247.0124 | FB3: 1693.2651 | FG3: 4595.9161 | FH3: 4924.1832 | FI3: 5002.3965 | FJ3: 5163.2043 | FK3: 5361.9679 | FL3: 4727.0668 | FM3: 4640.1993 | FN3: 4674.0557 | FO3: 5022.2713 | FP3: 4358.4884 | FQ3: 3774.0473 | FR3: 2999.6556 | FS3: 1318.25 | FT3: 4764.8018 | FU3: 4346.8766 | FV3: 4539.1126 | FW3: 3817.2788 | FX3: 4767.1011 | FY3: 3428.2705 | FZ3: 1367 | GA3: 4834.3636 | GB3: 4535.2797 | GC3: 3453.9344 | GD3: 3331.1915 | GE3: 3389.9013 | GF3: 2634.1773 | GG3: 1196.1532 | GH3: 3625.329 | GI3: 4241.9478 | GJ3: 4462.9635 | GK3: 3997.8422 | GL3: 3685.8333 | GM3: 2729.0406 | GN3: 1250.6972 | GO3: 3702.334 | GQ3: 4746.5814 | GR3: 4126.465 | GS3: 3734.2108 | GT3: 3227.4743 | GU3: 2139.3263 | GV3: 3056.3905 | GW3: 2929.6807 | GX3: 3101.4652 | GY3: 2908.8047 | GZ3: 2373.1806 | HA3: 1705.4687 | HB3: 1357.1209 | HC3: 3201.9895 | HD3: 3216.5555 | HE3: 3159.9939 | HF3: 2968.6551 | HG3: 2440.5962 | HH3: 1733.244 | HI3: 1322.6879 | HJ3: 2545.3851 | HK3: 2745.6781 | HL3: 2506.0806 | HM3: 2800.5191 | HN3: 2637.181 | HO3: 1595.0226 | HP3: 1215.4343 | HQ3: 2853.0993 | HR3: 2913.6332 | HS3: 2649.4175 | HT3: 2518.6604 | HU3: 2639.9913 | HV3: 1546.0147 | HW3: 1216.1949 | HX3: 2848.8186 | HY3: 2827.277 | HZ3: 2532.8076 | IA3: 2803.0812 | IB3: 2663.9862 | IC3: 2551.9231 | ID3: 2551.3622 | IE3: 2784.8067 | IF3: 2930.3577 | IG3: 3242.534 | IH3: 3499.7861 | II3: 3533.337 | IJ3: 2946.8151 | IK3: 2424.9271 | IL3: 2727.4929 | IM3: 2823.4128 | IN3: 2832.5862 | IO3: 2785.315 | IP3: 2860.5125 | IQ3: 2302.2758 | IR3: 2644.6627 | IS3: 3527.1359 | IT3: 3607.7659 | IU3: 4500.315 | IV3: 4594.3245 | IW3: 3505.1199 | IX3: 2522.9145 | IY3: 1844.6559 | IZ3: 3527.0427 | JA3: 3908.2106 | JB3: 3327.0611 | JC3: 3246.6864 | JD3: 3340.9515 | JE3: 1883.6603 | JF3: 1812.0833 | JG3: 3681.5833 | JH3: 4170.5 | JI3: 4376.0833 | JJ3: 4421.5 | JK3: 3968.523 | JL3: 1929.8333 | JM3: 1846.5833 | JN3: 4461.3333 | JO3: 4649.4167 | JP3: 4379.6696 | JQ3: 4096.9291 | JR3: 3840.8966 | JS3: 1956.7668 | JT3: 1850.9167 | JU3: 3879.8734 | JV3: 3928.1308 | JW3: 4894.2084 | JX3: 4789.11 | JY3: 4826.4486 | JZ3: 3179.2878 | KA3: 1717.5114 | KB3: 5491.7638 | KC3: 5609.4646 | KD3: 6038.4602 | KE3: 6084.0362 | KF3: 5737.423 | KG3: 5513.75 | KH3: 3894 | KI3: 5589.25 | KJ3: 5799.25 | KK3: 6031.1667 | KL3: 5954.5 | KM3: 5734.8333 | KN3: 3728.1667 | KO3: 2947.5 | KP3: 6445.6667 | KQ3: 6124.3333 | KR3: 5672.8265 | KS3: 5181.2847 | KT3: 5676.2181 | KU3: 3139.3048 | KV3: 2225.5 | KW3: 6422.689 | KX3: 6592.8333 | KY3: 5585.0015 | KZ3: 4557.8686 | LA3: 4503.849 | LB3: 2617.4283 | LC3: 2390.1667 | LD3: 4880.6667 | LE3: 4930 | LF3: 4705.8218 | LG3: 4258.377 | LH3: 4354.3691 | LI3: 2696.4167 | LJ3: 2383.75 | LK3: 5015.2249 | LL3: 5274.6228 | LM3: 4464.5187 | LN3: 4635.7811 | LO3: 4513.9645 | LP3: 2653.0731 | LQ3: 2377.5833 | LR3: 4670.0314 | LS3: 4542.225 | LT3: 4491.8873 | LU3: 4897.7435 | LV3: 5252.4243 | LW3: 3248.0092 | LX3: 2178.75 | LY3: 5887.3159 | LZ3: 5808.7309 | MA3: 5041.7018 | MB3: 4768.1476 | MC3: 4775.2428 | MD3: 3103.0578 | ME3: 2061.6499 | MF3: 5276.3753 | MG3: 5706.9825 | MH3: 5424.2606 | MI3: 5047.549 | MJ3: 4388.4036 | MK3: 2867.3889 | ML3: 2114.6667 | MM3: 4165.2853 | MN3: 4292.785 | MO3: 4205.6853 | MP3: 4358.351 | MQ3: 3633.6019 | MR3: 3605.7025 | MS3: 3629.6824 | MT3: 3978.6711 | MU3: 3954.25 | MV3: 3854.8692 | MW3: 3801.8879 | MX3: 3619.1096 | MY3: 2166.2966 | MZ3: 1949.8167 | NA3: 3826.25 | NB3: 3481.7343 | NC3: 2202.1183
A4: =SUM(C4:NC4) -> 43961163 | B4: Gerçekleşen Adet | D4: 110643 | E4: 87275 | F4: 63212 | G4: 52114 | H4: 77341 | I4: 84247 | J4: 48078 | K4: 59064 | L4: 55304 | M4: 62212 | N4: 64795 | O4: 76231 | P4: 71610 | Q4: 90966 | R4: 102665 | S4: 121547 | T4: 66659 | U4: 72913 | V4: 82607 | W4: 112240 | X4: 67455 | Y4: 77349 | Z4: 83403 | AA4: 65075 | AB4: 67819 | AC4: 61208 | AD4: 73830 | AE4: 70622 | AF4: 91810 | AG4: 79330 | AH4: 68062 | AI4: 66284 | AJ4: 63491 | AK4: 94199 | AL4: 101409 | AM4: 119888 | AN4: 121421 | AO4: 63936 | AP4: 72118 | AQ4: 116466 | AR4: 144028 | AS4: 125887 | AT4: 113816 | AU4: 81952 | AV4: 45981 | AW4: 59650 | AX4: 84244 | AY4: 121710 | AZ4: 109208 | BA4: 112908 | BB4: 81941 | BC4: 34554 | BD4: 42709 | BE4: 135248 | BF4: 120267 | BG4: 123095 | BH4: 93960 | BI4: 82351 | BJ4: 64175 | BK4: 24525 | BL4: 117118 | BM4: 109830 | BN4: 124806 | BO4: 133387 | BP4: 113264 | BQ4: 114516 | BR4: 62852 | BS4: 176068 | BT4: 167398 | BU4: 163484 | BV4: 155528 | BW4: 136973 | BX4: 116182 | BY4: 66153 | BZ4: 191236 | CA4: 205049 | CB4: 145045 | CC4: 225363 | CD4: 203259 | CE4: 183680 | CF4: 198523 | CG4: 228130 | CH4: 219831 | CI4: 181071 | CJ4: 120700 | CK4: 90268 | CL4: 33763 | CP4: 143413 | CQ4: 175715 | CR4: 119834 | CS4: 96258 | CT4: 68490 | CU4: 99862 | CV4: 117733 | CW4: 105885 | CX4: 112958 | CY4: 103147 | CZ4: 87374 | DA4: 65035 | DB4: 109830 | DC4: 144542 | DD4: 146665 | DE4: 142916 | DF4: 121675 | DG4: 81243 | DH4: 81171 | DI4: 115167 | DJ4: 126810 | DK4: 32564 | DM4: 121649 | DN4: 156877 | DO4: 133623 | DP4: 102947 | DQ4: 102389 | DR4: 99673 | DT4: 144138 | DU4: 120339 | DV4: 73888 | DW4: 152157 | DX4: 162349 | DY4: 174257 | DZ4: 167085 | EA4: 169871 | EB4: 116153 | EC4: 68892 | ED4: 183537 | EE4: 151468 | EF4: 166949 | EG4: 182637 | EH4: 152672 | EI4: 113339 | EJ4: 67363 | EK4: 159357 | EL4: 192422 | EM4: 181673 | EN4: 200658 | EO4: 174480 | EP4: 120564 | EQ4: 65818 | ER4: 181063 | ES4: 209684 | ET4: 212103 | EU4: 211747 | EV4: 205354 | EW4: 236378 | EX4: 186779 | EY4: 204907 | EZ4: 161060 | FA4: 84621 | FB4: 43095 | FG4: 111470 | FH4: 186181 | FI4: 188427 | FJ4: 184881 | FK4: 205036 | FL4: 191761 | FM4: 188258 | FN4: 186599 | FO4: 175200 | FP4: 179031 | FQ4: 128620 | FR4: 116852 | FS4: 56689 | FT4: 135330 | FU4: 130895 | FV4: 169408 | FW4: 135565 | FX4: 182919 | FY4: 115342 | FZ4: 67947 | GA4: 173654 | GB4: 178754 | GC4: 118938 | GD4: 115261 | GE4: 117441 | GF4: 75693 | GG4: 48596 | GH4: 90150 | GI4: 139724 | GJ4: 167021 | GK4: 146331 | GL4: 128140 | GM4: 110366 | GN4: 55403 | GO4: 94051 | GQ4: 166386 | GR4: 143024 | GS4: 145218 | GT4: 119545 | GU4: 87109 | GV4: 113604 | GW4: 105218 | GX4: 128606 | GY4: 109577 | GZ4: 72392 | HA4: 71596 | HB4: 58561 | HC4: 120816 | HD4: 94496 | HE4: 129259 | HF4: 113090 | HG4: 94472 | HH4: 63962 | HI4: 65009 | HJ4: 81924 | HK4: 111184 | HL4: 88912 | HM4: 93653 | HN4: 89852 | HO4: 59841 | HP4: 63630 | HQ4: 111024 | HR4: 112282 | HS4: 113795 | HT4: 84323 | HU4: 100091 | HV4: 58131 | HW4: 54737 | HX4: 103777 | HY4: 79747 | HZ4: 97383 | IA4: 115745 | IB4: 115727 | IC4: 103268 | ID4: 105953 | IE4: 104098 | IF4: 106824 | IG4: 113974 | IH4: 139680 | II4: 138356 | IJ4: 123752 | IK4: 89376 | IL4: 111120 | IM4: 113341 | IN4: 105405 | IO4: 103891 | IP4: 98088 | IQ4: 101476 | IR4: 99087 | IS4: 120281 | IT4: 120263 | IU4: 165327 | IV4: 171410 | IW4: 129333 | IX4: 97858 | IY4: 57650 | IZ4: 121370 | JA4: 143001 | JB4: 146862 | JC4: 130909 | JD4: 106338 | JE4: 83419 | JF4: 74482 | JG4: 133599 | JH4: 173594 | JI4: 162614 | JJ4: 183167 | JK4: 180184 | JL4: 84488 | JM4: 67238 | JN4: 145944 | JO4: 189656 | JP4: 162989 | JQ4: 168481 | JR4: 137762 | JS4: 84001 | JT4: 72512 | JU4: 149075 | JV4: 164266 | JW4: 173891 | JX4: 177190 | JY4: 179760 | JZ4: 103215 | KA4: 67615 | KB4: 181138 | KC4: 171842 | KD4: 203447 | KE4: 213845 | KF4: 214373 | KG4: 216578 | KH4: 153818 | KI4: 199107 | KJ4: 215894 | KK4: 203954 | KL4: 212985 | KM4: 197455 | KN4: 145735 | KO4: 112433 | KP4: 196571 | KQ4: 202583 | KR4: 211064 | KS4: 174986 | KT4: 156181 | KU4: 99474 | KV4: 84537 | KW4: 158534 | KX4: 194645 | KY4: 188010 | KZ4: 167672 | LA4: 86129 | LB4: 99527 | LC4: 89670 | LD4: 115079 | LE4: 117252 | LF4: 130169 | LG4: 132371 | LH4: 118039 | LI4: 97736 | LJ4: 97473 | LK4: 125909 | LL4: 176181 | LM4: 156073 | LN4: 129627 | LO4: 134785 | LP4: 81720 | LQ4: 75000 | LR4: 111431 | LS4: 145629 | LT4: 159338 | LU4: 161208 | LV4: 143780 | LW4: 87582 | LX4: 82023 | LY4: 173818 | LZ4: 167365 | MA4: 175196 | MB4: 155446 | MC4: 159897 | MD4: 96131 | ME4: 71848 | MF4: 162076 | MG4: 188867 | MH4: 196941 | MI4: 191777 | MJ4: 160227 | MK4: 111542 | ML4: 84103 | MM4: 127258 | MN4: 130803 | MO4: 137569 | MP4: 135661 | MQ4: 133999 | MR4: 128412 | MS4: 132062 | MT4: 128960 | MU4: 129343 | MV4: 136976 | MW4: 142075 | MX4: 124170 | MY4: 89809 | MZ4: 81836 | NA4: 136048 | NB4: 138162 | NC4: 94243
